2025-05-25 01:39:29,574 ERROR: Exception on /api/parts [POST] [in /usr/local/lib/python3.11/site-packages/flask/app.py:875]
Traceback (most recent call last):
  File "/usr/local/lib/python3.11/site-packages/sqlalchemy/engine/base.py", line 1963, in _exec_single_context
    self.dialect.do_execute(
  File "/usr/local/lib/python3.11/site-packages/sqlalchemy/engine/default.py", line 943, in do_execute
    cursor.execute(statement, parameters)
  File "/usr/local/lib/python3.11/site-packages/pymysql/cursors.py", line 153, in execute
    result = self._query(query)
             ^^^^^^^^^^^^^^^^^^
  File "/usr/local/lib/python3.11/site-packages/pymysql/cursors.py", line 322, in _query
    conn.query(q)
  File "/usr/local/lib/python3.11/site-packages/pymysql/connections.py", line 563, in query
    self._affected_rows = self._read_query_result(unbuffered=unbuffered)
                          ^^^^^^^^^^^^^^^^^^^^^^^^^^^^^^^^^^^^^^^^^^^^^^
  File "/usr/local/lib/python3.11/site-packages/pymysql/connections.py", line 825, in _read_query_result
    result.read()
  File "/usr/local/lib/python3.11/site-packages/pymysql/connections.py", line 1199, in read
    first_packet = self.connection._read_packet()
                   ^^^^^^^^^^^^^^^^^^^^^^^^^^^^^^
  File "/usr/local/lib/python3.11/site-packages/pymysql/connections.py", line 775, in _read_packet
    packet.raise_for_error()
  File "/usr/local/lib/python3.11/site-packages/pymysql/protocol.py", line 219, in raise_for_error
    err.raise_mysql_exception(self._data)
  File "/usr/local/lib/python3.11/site-packages/pymysql/err.py", line 150, in raise_mysql_exception
    raise errorclass(errno, errval)
pymysql.err.IntegrityError: (1048, "Column 'raw_material' cannot be null")

The above exception was the direct cause of the following exception:

Traceback (most recent call last):
  File "/usr/local/lib/python3.11/site-packages/flask/app.py", line 1511, in wsgi_app
    response = self.full_dispatch_request()
               ^^^^^^^^^^^^^^^^^^^^^^^^^^^^
  File "/usr/local/lib/python3.11/site-packages/flask/app.py", line 919, in full_dispatch_request
    rv = self.handle_user_exception(e)
         ^^^^^^^^^^^^^^^^^^^^^^^^^^^^^
  File "/usr/local/lib/python3.11/site-packages/flask_cors/extension.py", line 176, in wrapped_function
    return cors_after_request(app.make_response(f(*args, **kwargs)))
                                                ^^^^^^^^^^^^^^^^^^
  File "/usr/local/lib/python3.11/site-packages/flask/app.py", line 917, in full_dispatch_request
    rv = self.dispatch_request()
         ^^^^^^^^^^^^^^^^^^^^^^^
  File "/usr/local/lib/python3.11/site-packages/flask/app.py", line 902, in dispatch_request
    return self.ensure_sync(self.view_functions[rule.endpoint])(**view_args)  # type: ignore[no-any-return]
           ^^^^^^^^^^^^^^^^^^^^^^^^^^^^^^^^^^^^^^^^^^^^^^^^^^^^^^^^^^^^^^^^^
  File "/app/app/decorators.py", line 124, in wrapper
    return fn(*args, **kwargs)
           ^^^^^^^^^^^^^^^^^^^
  File "/app/app/routes.py", line 431, in create_part
    db.session.commit()
  File "/usr/local/lib/python3.11/site-packages/sqlalchemy/orm/scoping.py", line 599, in commit
    return self._proxied.commit()
           ^^^^^^^^^^^^^^^^^^^^^^
  File "/usr/local/lib/python3.11/site-packages/sqlalchemy/orm/session.py", line 2032, in commit
    trans.commit(_to_root=True)
  File "<string>", line 2, in commit
  File "/usr/local/lib/python3.11/site-packages/sqlalchemy/orm/state_changes.py", line 139, in _go
    ret_value = fn(self, *arg, **kw)
                ^^^^^^^^^^^^^^^^^^^^
  File "/usr/local/lib/python3.11/site-packages/sqlalchemy/orm/session.py", line 1313, in commit
    self._prepare_impl()
  File "<string>", line 2, in _prepare_impl
  File "/usr/local/lib/python3.11/site-packages/sqlalchemy/orm/state_changes.py", line 139, in _go
    ret_value = fn(self, *arg, **kw)
                ^^^^^^^^^^^^^^^^^^^^
  File "/usr/local/lib/python3.11/site-packages/sqlalchemy/orm/session.py", line 1288, in _prepare_impl
    self.session.flush()
  File "/usr/local/lib/python3.11/site-packages/sqlalchemy/orm/session.py", line 4345, in flush
    self._flush(objects)
  File "/usr/local/lib/python3.11/site-packages/sqlalchemy/orm/session.py", line 4480, in _flush
    with util.safe_reraise():
  File "/usr/local/lib/python3.11/site-packages/sqlalchemy/util/langhelpers.py", line 224, in __exit__
    raise exc_value.with_traceback(exc_tb)
  File "/usr/local/lib/python3.11/site-packages/sqlalchemy/orm/session.py", line 4441, in _flush
    flush_context.execute()
  File "/usr/local/lib/python3.11/site-packages/sqlalchemy/orm/unitofwork.py", line 466, in execute
    rec.execute(self)
  File "/usr/local/lib/python3.11/site-packages/sqlalchemy/orm/unitofwork.py", line 642, in execute
    util.preloaded.orm_persistence.save_obj(
  File "/usr/local/lib/python3.11/site-packages/sqlalchemy/orm/persistence.py", line 93, in save_obj
    _emit_insert_statements(
  File "/usr/local/lib/python3.11/site-packages/sqlalchemy/orm/persistence.py", line 1233, in _emit_insert_statements
    result = connection.execute(
             ^^^^^^^^^^^^^^^^^^^
  File "/usr/local/lib/python3.11/site-packages/sqlalchemy/engine/base.py", line 1415, in execute
    return meth(
           ^^^^^
  File "/usr/local/lib/python3.11/site-packages/sqlalchemy/sql/elements.py", line 523, in _execute_on_connection
    return connection._execute_clauseelement(
           ^^^^^^^^^^^^^^^^^^^^^^^^^^^^^^^^^^
  File "/usr/local/lib/python3.11/site-packages/sqlalchemy/engine/base.py", line 1637, in _execute_clauseelement
    ret = self._execute_context(
          ^^^^^^^^^^^^^^^^^^^^^^
  File "/usr/local/lib/python3.11/site-packages/sqlalchemy/engine/base.py", line 1842, in _execute_context
    return self._exec_single_context(
           ^^^^^^^^^^^^^^^^^^^^^^^^^^
  File "/usr/local/lib/python3.11/site-packages/sqlalchemy/engine/base.py", line 1982, in _exec_single_context
    self._handle_dbapi_exception(
  File "/usr/local/lib/python3.11/site-packages/sqlalchemy/engine/base.py", line 2351, in _handle_dbapi_exception
    raise sqlalchemy_exception.with_traceback(exc_info[2]) from e
  File "/usr/local/lib/python3.11/site-packages/sqlalchemy/engine/base.py", line 1963, in _exec_single_context
    self.dialect.do_execute(
  File "/usr/local/lib/python3.11/site-packages/sqlalchemy/engine/default.py", line 943, in do_execute
    cursor.execute(statement, parameters)
  File "/usr/local/lib/python3.11/site-packages/pymysql/cursors.py", line 153, in execute
    result = self._query(query)
             ^^^^^^^^^^^^^^^^^^
  File "/usr/local/lib/python3.11/site-packages/pymysql/cursors.py", line 322, in _query
    conn.query(q)
  File "/usr/local/lib/python3.11/site-packages/pymysql/connections.py", line 563, in query
    self._affected_rows = self._read_query_result(unbuffered=unbuffered)
                          ^^^^^^^^^^^^^^^^^^^^^^^^^^^^^^^^^^^^^^^^^^^^^^
  File "/usr/local/lib/python3.11/site-packages/pymysql/connections.py", line 825, in _read_query_result
    result.read()
  File "/usr/local/lib/python3.11/site-packages/pymysql/connections.py", line 1199, in read
    first_packet = self.connection._read_packet()
                   ^^^^^^^^^^^^^^^^^^^^^^^^^^^^^^
  File "/usr/local/lib/python3.11/site-packages/pymysql/connections.py", line 775, in _read_packet
    packet.raise_for_error()
  File "/usr/local/lib/python3.11/site-packages/pymysql/protocol.py", line 219, in raise_for_error
    err.raise_mysql_exception(self._data)
  File "/usr/local/lib/python3.11/site-packages/pymysql/err.py", line 150, in raise_mysql_exception
    raise errorclass(errno, errval)
sqlalchemy.exc.IntegrityError: (pymysql.err.IntegrityError) (1048, "Column 'raw_material' cannot be null")
[SQL: INSERT INTO parts (numeric_id, part_number, name, description, material, revision, status, quantity_on_hand, quantity_on_order, project_id, type, parent_id, notes, source_material, have_material, quantity_required, cut_length, priority, drawing_created, quantity, raw_material, machine_id, subteam_id, subsystem_id, created_at, updated_at) VALUES (%(numeric_id)s, %(part_number)s, %(name)s, %(description)s, %(material)s, %(revision)s, %(status)s, %(quantity_on_hand)s, %(quantity_on_order)s, %(project_id)s, %(type)s, %(parent_id)s, %(notes)s, %(source_material)s, %(have_material)s, %(quantity_required)s, %(cut_length)s, %(priority)s, %(drawing_created)s, %(quantity)s, %(raw_material)s, %(machine_id)s, %(subteam_id)s, %(subsystem_id)s, %(created_at)s, %(updated_at)s)]
[parameters: {'numeric_id': 1100, 'part_number': 'br-A-1100', 'name': 'kiajf', 'description': 'fhaihe', 'material': None, 'revision': None, 'status': 'In Design', 'quantity_on_hand': 0, 'quantity_on_order': 0, 'project_id': 1, 'type': 'assembly', 'parent_id': 4, 'notes': 'fhaihe', 'source_material': '', 'have_material': 0, 'quantity_required': '', 'cut_length': '', 'priority': 1, 'drawing_created': 0, 'quantity': 1, 'raw_material': None, 'machine_id': None, 'subteam_id': 4, 'subsystem_id': 4, 'created_at': datetime.datetime(2025, 5, 25, 1, 39, 29, 573465), 'updated_at': datetime.datetime(2025, 5, 25, 1, 39, 29, 573467)}]
(Background on this error at: https://sqlalche.me/e/20/gkpj)
2025-05-25 01:40:18,862 INFO: BroncoPartsV2 application starting up [in /app/app/__init__.py:76]
2025-05-25 01:41:54,904 INFO: BroncoPartsV2 application starting up [in /app/app/__init__.py:76]
2025-05-25 01:42:17,700 INFO: BroncoPartsV2 application starting up [in /app/app/__init__.py:76]
2025-05-25 01:42:18,204 INFO: BroncoPartsV2 application starting up [in /app/app/__init__.py:76]
2025-05-25 01:42:18,723 INFO: BroncoPartsV2 application starting up [in /app/app/__init__.py:76]
2025-05-25 01:42:26,642 WARNING: Airtable sync for part br-A-1100: Subsystem name 'Chassis' is not a valid option in Airtable. Field will be omitted. Valid options: ['Accumulator', 'Brake System', 'Cooling', 'Drivetrain', 'Ergonomics', 'Frame', 'Hubs', 'Pedal Box', 'Spring Systems', 'Steering', 'Suspension Structures', 'Tractive System', 'Paneling', 'Data Aquisition', 'PCB', 'Accumulator Control', 'Jigs', 'GLV Power', 'Shutdown Circuit', 'Driver UI'] [in /app/app/services/airtable_service.py:111]
